<?xml version="1.0" ?>
<!-- =================================================================================== -->
<!-- |    This document was autogenerated by xacro from urdf\robotArm_ver7.xacro.temp  | -->
<!-- |    EDITING THIS FILE BY HAND IS NOT RECOMMENDED                                 | -->
<!-- =================================================================================== -->
<robot xmlns:xacro="http://www.ros.org/wiki/xacro" name="robotArm_ver7">
  <material name="silver">
    <color rgba="0.700 0.700 0.700 1.000"/>
  </material>
  <transmission name="Revolute 0_tran">
    <type>transmission_interface/SimpleTransmission</type>
    <joint name="Revolute 0">
      <hardwareInterface>hardware_interface/EffortJointInterface</hardwareInterface>
    </joint>
    <actuator name="Revolute 0_actr">
      <hardwareInterface>hardware_interface/EffortJointInterface</hardwareInterface>
      <mechanicalReduction>1</mechanicalReduction>
    </actuator>
  </transmission>
  <transmission name="Revolute 6_tran">
    <type>transmission_interface/SimpleTransmission</type>
    <joint name="Revolute 6">
      <hardwareInterface>hardware_interface/EffortJointInterface</hardwareInterface>
    </joint>
    <actuator name="Revolute 6_actr">
      <hardwareInterface>hardware_interface/EffortJointInterface</hardwareInterface>
      <mechanicalReduction>1</mechanicalReduction>
    </actuator>
  </transmission>
  <transmission name="Revolute 7_tran">
    <type>transmission_interface/SimpleTransmission</type>
    <joint name="Revolute 7">
      <hardwareInterface>hardware_interface/EffortJointInterface</hardwareInterface>
    </joint>
    <actuator name="Revolute 7_actr">
      <hardwareInterface>hardware_interface/EffortJointInterface</hardwareInterface>
      <mechanicalReduction>1</mechanicalReduction>
    </actuator>
  </transmission>
  <transmission name="Revolute 8_tran">
    <type>transmission_interface/SimpleTransmission</type>
    <joint name="Revolute 8">
      <hardwareInterface>hardware_interface/EffortJointInterface</hardwareInterface>
    </joint>
    <actuator name="Revolute 8_actr">
      <hardwareInterface>hardware_interface/EffortJointInterface</hardwareInterface>
      <mechanicalReduction>1</mechanicalReduction>
    </actuator>
  </transmission>
  <transmission name="Revolute 9_tran">
    <type>transmission_interface/SimpleTransmission</type>
    <joint name="Revolute 9">
      <hardwareInterface>hardware_interface/EffortJointInterface</hardwareInterface>
    </joint>
    <actuator name="Revolute 9_actr">
      <hardwareInterface>hardware_interface/EffortJointInterface</hardwareInterface>
      <mechanicalReduction>1</mechanicalReduction>
    </actuator>
  </transmission>
  <transmission name="Revolute 3_tran">
    <type>transmission_interface/SimpleTransmission</type>
    <joint name="Revolute 3">
      <hardwareInterface>hardware_interface/EffortJointInterface</hardwareInterface>
    </joint>
    <actuator name="Revolute 3_actr">
      <hardwareInterface>hardware_interface/EffortJointInterface</hardwareInterface>
      <mechanicalReduction>1</mechanicalReduction>
    </actuator>
  </transmission>
  <transmission name="Revolute 4_tran">
    <type>transmission_interface/SimpleTransmission</type>
    <joint name="Revolute 4">
      <hardwareInterface>hardware_interface/EffortJointInterface</hardwareInterface>
    </joint>
    <actuator name="Revolute 4_actr">
      <hardwareInterface>hardware_interface/EffortJointInterface</hardwareInterface>
      <mechanicalReduction>1</mechanicalReduction>
    </actuator>
  </transmission>
  <transmission name="Revolute 5_tran">
    <type>transmission_interface/SimpleTransmission</type>
    <joint name="Revolute 5">
      <hardwareInterface>hardware_interface/EffortJointInterface</hardwareInterface>
    </joint>
    <actuator name="Revolute 5_actr">
      <hardwareInterface>hardware_interface/EffortJointInterface</hardwareInterface>
      <mechanicalReduction>1</mechanicalReduction>
    </actuator>
  </transmission>
  <transmission name="Revolute 19_tran">
    <type>transmission_interface/SimpleTransmission</type>
    <joint name="Revolute 19">
      <hardwareInterface>hardware_interface/EffortJointInterface</hardwareInterface>
    </joint>
    <actuator name="Revolute 19_actr">
      <hardwareInterface>hardware_interface/EffortJointInterface</hardwareInterface>
      <mechanicalReduction>1</mechanicalReduction>
    </actuator>
  </transmission>
  <transmission name="Revolute 21_tran">
    <type>transmission_interface/SimpleTransmission</type>
    <joint name="Revolute 21">
      <hardwareInterface>hardware_interface/EffortJointInterface</hardwareInterface>
    </joint>
    <actuator name="Revolute 21_actr">
      <hardwareInterface>hardware_interface/EffortJointInterface</hardwareInterface>
      <mechanicalReduction>1</mechanicalReduction>
    </actuator>
  </transmission>
  <!-- omitted .gazebo include -->
  <link name="base_link">
    <inertial>
      <origin xyz="2.989375374043843 1.1395251464843752 0.07612872006595212" rpy="0 0 0"/>
      <mass value="1.6067306789990348"/>
      <inertia ixx="0.003521" iyy="0.006468" izz="0.008802" ixy="0.0" iyz="0.0" ixz="0.0"/>
    </inertial>
    <visual>
      <origin xyz="0 0 0" rpy="0 0 0"/>
      <geometry>
        <mesh filename="package://robotArm_ver7_description/meshes/base_link.stl" scale="0.001 0.001 0.001"/>
      </geometry>
      <material name="silver"/>
    </visual>
    <collision>
      <origin xyz="0 0 0" rpy="0 0 0"/>
      <geometry>
        <mesh filename="package://robotArm_ver7_description/meshes/base_link.stl" scale="0.001 0.001 0.001"/>
      </geometry>
    </collision>
  </link>
  <link name="link_1_1">
    <inertial>
      <origin xyz="2.079701451052074e-07 1.4648437618447474e-07 0.04484473463010137" rpy="0 0 0"/>
      <mass value="0.8724221516717876"/>
      <inertia ixx="0.000529" iyy="0.000636" izz="0.000308" ixy="-0.0" iyz="-0.0" ixz="-0.0"/>
    </inertial>
    <visual>
      <origin xyz="-2.989375 -1.139525 -0.122186" rpy="0 0 0"/>
      <geometry>
        <mesh filename="package://robotArm_ver7_description/meshes/link_1_1.stl" scale="0.001 0.001 0.001"/>
      </geometry>
      <material name="silver"/>
    </visual>
    <collision>
      <origin xyz="-2.989375 -1.139525 -0.122186" rpy="0 0 0"/>
      <geometry>
        <mesh filename="package://robotArm_ver7_description/meshes/link_1_1.stl" scale="0.001 0.001 0.001"/>
      </geometry>
    </collision>
  </link>
  <link name="grap_1_1">
    <inertial>
      <origin xyz="-0.0011124634317667415 -0.032767957693791594 0.005980632077344561" rpy="0 0 0"/>
      <mass value="0.040626783640930614"/>
      <inertia ixx="2.7e-05" iyy="6e-06" izz="2.3e-05" ixy="-2e-06" iyz="7e-06" ixz="1e-06"/>
    </inertial>
    <visual>
      <origin xyz="-3.014333 -1.131222 -0.778853" rpy="0 0 0"/>
      <geometry>
        <mesh filename="package://robotArm_ver7_description/meshes/grap_1_1.stl" scale="0.001 0.001 0.001"/>
      </geometry>
      <material name="silver"/>
    </visual>
    <collision>
      <origin xyz="-3.014333 -1.131222 -0.778853" rpy="0 0 0"/>
      <geometry>
        <mesh filename="package://robotArm_ver7_description/meshes/grap_1_1.stl" scale="0.001 0.001 0.001"/>
      </geometry>
    </collision>
  </link>
  <link name="grap_2_1">
    <inertial>
      <origin xyz="-0.0011124634317360993 0.03276825066262434 0.0059806320774223876" rpy="0 0 0"/>
      <mass value="0.040626783640931044"/>
      <inertia ixx="2.7e-05" iyy="6e-06" izz="2.3e-05" ixy="2e-06" iyz="-7e-06" ixz="1e-06"/>
    </inertial>
    <visual>
      <origin xyz="-3.014333 -1.156222 -0.778853" rpy="0 0 0"/>
      <geometry>
        <mesh filename="package://robotArm_ver7_description/meshes/grap_2_1.stl" scale="0.001 0.001 0.001"/>
      </geometry>
      <material name="silver"/>
    </visual>
    <collision>
      <origin xyz="-3.014333 -1.156222 -0.778853" rpy="0 0 0"/>
      <geometry>
        <mesh filename="package://robotArm_ver7_description/meshes/grap_2_1.stl" scale="0.001 0.001 0.001"/>
      </geometry>
    </collision>
  </link>
  <link name="grap1_2_1">
    <inertial>
      <origin xyz="0.0011127473107239716 -0.032767957693790706 0.005980632077423831" rpy="0 0 0"/>
      <mass value="0.04062678364093068"/>
      <inertia ixx="2.7e-05" iyy="6e-06" izz="2.3e-05" ixy="2e-06" iyz="7e-06" ixz="-1e-06"/>
    </inertial>
    <visual>
      <origin xyz="-2.964333 -1.131222 -0.778853" rpy="0 0 0"/>
      <geometry>
        <mesh filename="package://robotArm_ver7_description/meshes/grap1_2_1.stl" scale="0.001 0.001 0.001"/>
      </geometry>
      <material name="silver"/>
    </visual>
    <collision>
      <origin xyz="-2.964333 -1.131222 -0.778853" rpy="0 0 0"/>
      <geometry>
        <mesh filename="package://robotArm_ver7_description/meshes/grap1_2_1.stl" scale="0.001 0.001 0.001"/>
      </geometry>
    </collision>
  </link>
  <link name="grap2_2_1">
    <inertial>
      <origin xyz="0.001112747310715978 0.032768250662611464 0.005980632077452697" rpy="0 0 0"/>
      <mass value="0.04062678364093034"/>
      <inertia ixx="2.7e-05" iyy="6e-06" izz="2.3e-05" ixy="-2e-06" iyz="-7e-06" ixz="-1e-06"/>
    </inertial>
    <visual>
      <origin xyz="-2.964333 -1.156222 -0.778853" rpy="0 0 0"/>
      <geometry>
        <mesh filename="package://robotArm_ver7_description/meshes/grap2_2_1.stl" scale="0.001 0.001 0.001"/>
      </geometry>
      <material name="silver"/>
    </visual>
    <collision>
      <origin xyz="-2.964333 -1.156222 -0.778853" rpy="0 0 0"/>
      <geometry>
        <mesh filename="package://robotArm_ver7_description/meshes/grap2_2_1.stl" scale="0.001 0.001 0.001"/>
      </geometry>
    </collision>
  </link>
  <link name="Wrist1_1">
    <inertial>
      <origin xyz="3.7404379060745896e-07 -0.02000177002189374 0.04507703257348883" rpy="0 0 0"/>
      <mass value="0.544858404723334"/>
      <inertia ixx="0.000822" iyy="0.000329" izz="0.000562" ixy="0.0" iyz="0.000113" ixz="-0.0"/>
    </inertial>
    <visual>
      <origin xyz="-2.989375 -1.142023 -0.64097" rpy="0 0 0"/>
      <geometry>
        <mesh filename="package://robotArm_ver7_description/meshes/Wrist1_1.stl" scale="0.001 0.001 0.001"/>
      </geometry>
      <material name="silver"/>
    </visual>
    <collision>
      <origin xyz="-2.989375 -1.142023 -0.64097" rpy="0 0 0"/>
      <geometry>
        <mesh filename="package://robotArm_ver7_description/meshes/Wrist1_1.stl" scale="0.001 0.001 0.001"/>
      </geometry>
    </collision>
  </link>
  <link name="Wrist2_1">
    <inertial>
      <origin xyz="0.010085452867119482 0.021157588279396622 0.006057094515764971" rpy="0 0 0"/>
      <mass value="0.3986034277980482"/>
      <inertia ixx="9.1e-05" iyy="0.000131" izz="0.000113" ixy="-6e-06" iyz="-4e-06" ixz="-2e-06"/>
    </inertial>
    <visual>
      <origin xyz="-2.989375 -1.121022 -0.70742" rpy="0 0 0"/>
      <geometry>
        <mesh filename="package://robotArm_ver7_description/meshes/Wrist2_1.stl" scale="0.001 0.001 0.001"/>
      </geometry>
      <material name="silver"/>
    </visual>
    <collision>
      <origin xyz="-2.989375 -1.121022 -0.70742" rpy="0 0 0"/>
      <geometry>
        <mesh filename="package://robotArm_ver7_description/meshes/Wrist2_1.stl" scale="0.001 0.001 0.001"/>
      </geometry>
    </collision>
  </link>
  <link name="link_4_1">
    <inertial>
      <origin xyz="1.4193951924923454e-07 1.464844152643252e-07 0.01816842213440839" rpy="0 0 0"/>
      <mass value="0.1836674229836166"/>
      <inertia ixx="7.1e-05" iyy="0.000103" izz="0.0001" ixy="-0.0" iyz="-0.0" ixz="0.0"/>
    </inertial>
    <visual>
      <origin xyz="-2.989333 -1.143722 -0.736653" rpy="0 0 0"/>
      <geometry>
        <mesh filename="package://robotArm_ver7_description/meshes/link_4_1.stl" scale="0.001 0.001 0.001"/>
      </geometry>
      <material name="silver"/>
    </visual>
    <collision>
      <origin xyz="-2.989333 -1.143722 -0.736653" rpy="0 0 0"/>
      <geometry>
        <mesh filename="package://robotArm_ver7_description/meshes/link_4_1.stl" scale="0.001 0.001 0.001"/>
      </geometry>
    </collision>
  </link>
  <link name="link_2_1">
    <inertial>
      <origin xyz="2.930768165931852e-07 1.4648438195763447e-07 0.13199352594951722" rpy="0 0 0"/>
      <mass value="1.7894494256516804"/>
      <inertia ixx="0.007559" iyy="0.007762" izz="0.000473" ixy="0.0" iyz="0.0" ixz="0.0"/>
    </inertial>
    <visual>
      <origin xyz="-2.989375 -1.139525 -0.192528" rpy="0 0 0"/>
      <geometry>
        <mesh filename="package://robotArm_ver7_description/meshes/link_2_1.stl" scale="0.001 0.001 0.001"/>
      </geometry>
      <material name="silver"/>
    </visual>
    <collision>
      <origin xyz="-2.989375 -1.139525 -0.192528" rpy="0 0 0"/>
      <geometry>
        <mesh filename="package://robotArm_ver7_description/meshes/link_2_1.stl" scale="0.001 0.001 0.001"/>
      </geometry>
    </collision>
  </link>
  <link name="link_3_1">
    <inertial>
      <origin xyz="3.740437874988345e-07 -0.008179960596720992 0.14907072470751842" rpy="0 0 0"/>
      <mass value="2.3011672222568587"/>
      <inertia ixx="0.010731" iyy="0.010238" izz="0.001122" ixy="0.0" iyz="0.001076" ixz="0.0"/>
    </inertial>
    <visual>
      <origin xyz="-2.989375 -1.139525 -0.40687" rpy="0 0 0"/>
      <geometry>
        <mesh filename="package://robotArm_ver7_description/meshes/link_3_1.stl" scale="0.001 0.001 0.001"/>
      </geometry>
      <material name="silver"/>
    </visual>
    <collision>
      <origin xyz="-2.989375 -1.139525 -0.40687" rpy="0 0 0"/>
      <geometry>
        <mesh filename="package://robotArm_ver7_description/meshes/link_3_1.stl" scale="0.001 0.001 0.001"/>
      </geometry>
    </collision>
  </link>
  <joint name="Revolute 0" type="revolute">
    <origin xyz="2.989375 1.139525 0.122186" rpy="0 0 0"/>
    <parent link="base_link"/>
    <child link="link_1_1"/>
    <axis xyz="0.0 0.0 1.0"/>
    <limit upper="1.570796" lower="-1.570796" effort="100" velocity="100"/>
  </joint>
  <joint name="Revolute 6" type="revolute">
    <origin xyz="0.025 -0.0125 0.0422" rpy="0 0 0"/>
    <parent link="link_4_1"/>
    <child link="grap_1_1"/>
    <axis xyz="1.0 0.0 0.0"/>
    <limit upper="6.283185" lower="0.0" effort="100" velocity="100"/>
  </joint>
  <joint name="Revolute 7" type="revolute">
    <origin xyz="0.025 0.0125 0.0422" rpy="0 0 0"/>
    <parent link="link_4_1"/>
    <child link="grap_2_1"/>
    <axis xyz="1.0 0.0 0.0"/>
    <limit upper="6.283185" lower="0.0" effort="100" velocity="100"/>
  </joint>
  <joint name="Revolute 8" type="revolute">
    <origin xyz="-0.025 -0.0125 0.0422" rpy="0 0 0"/>
    <parent link="link_4_1"/>
    <child link="grap1_2_1"/>
    <axis xyz="-1.0 -0.0 -0.0"/>
    <limit upper="6.283185" lower="0.0" effort="100" velocity="100"/>
  </joint>
  <joint name="Revolute 9" type="revolute">
    <origin xyz="-0.025 0.0125 0.0422" rpy="0 0 0"/>
    <parent link="link_4_1"/>
    <child link="grap2_2_1"/>
    <axis xyz="-1.0 -0.0 -0.0"/>
    <limit upper="6.283185" lower="0.0" effort="100" velocity="100"/>
  </joint>
  <joint name="Revolute 3" type="revolute">
    <origin xyz="0.0 0.002498 0.2341" rpy="0 0 0"/>
    <parent link="link_3_1"/>
    <child link="Wrist1_1"/>
    <axis xyz="-0.0 0.0 1.0"/>
    <limit upper="3.141593" lower="0.0" effort="100" velocity="100"/>
  </joint>
  <joint name="Revolute 4" type="revolute">
    <origin xyz="0.0 -0.021001 0.06645" rpy="0 0 0"/>
    <parent link="Wrist1_1"/>
    <child link="Wrist2_1"/>
    <axis xyz="0.0 1.0 -0.0"/>
    <limit upper="1.570796" lower="-1.570796" effort="100" velocity="100"/>
  </joint>
  <joint name="Revolute 5" type="revolute">
    <origin xyz="-4.2e-05 0.0227 0.029233" rpy="0 0 0"/>
    <parent link="Wrist2_1"/>
    <child link="link_4_1"/>
    <axis xyz="-0.0 0.0 1.0"/>
    <limit upper="6.283185" lower="0.0" effort="100" velocity="100"/>
  </joint>
  <joint name="Revolute 19" type="revolute">
    <origin xyz="0.0 0.0 0.070342" rpy="0 0 0"/>
    <parent link="link_1_1"/>
    <child link="link_2_1"/>
    <axis xyz="-1.0 0.0 -0.0"/>
    <limit upper="1.396263" lower="-1.570796" effort="100" velocity="100"/>
  </joint>
  <joint name="Revolute 21" type="revolute">
    <origin xyz="0.0 0.0 0.214342" rpy="0 0 0"/>
    <parent link="link_2_1"/>
    <child link="link_3_1"/>
    <axis xyz="-1.0 -0.0 -0.0"/>
    <limit upper="1.570796" lower="0.0" effort="100" velocity="100"/>
  </joint>
</robot>
