<?xml version="1.0" ?>
<!-- =================================================================================== -->
<!-- |    This document was autogenerated by xacro from urdf\robot_ver7.xacro.temp     | -->
<!-- |    EDITING THIS FILE BY HAND IS NOT RECOMMENDED                                 | -->
<!-- =================================================================================== -->
<robot xmlns:xacro="http://www.ros.org/wiki/xacro" name="robot_ver7">
  <material name="silver">
    <color rgba="0.700 0.700 0.700 1.000"/>
  </material>
  <transmission name="Revolute 1_tran">
    <type>transmission_interface/SimpleTransmission</type>
    <joint name="Revolute 1">
      <hardwareInterface>hardware_interface/EffortJointInterface</hardwareInterface>
    </joint>
    <actuator name="Revolute 1_actr">
      <hardwareInterface>hardware_interface/EffortJointInterface</hardwareInterface>
      <mechanicalReduction>1</mechanicalReduction>
    </actuator>
  </transmission>
  <transmission name="Revolute 2_tran">
    <type>transmission_interface/SimpleTransmission</type>
    <joint name="Revolute 2">
      <hardwareInterface>hardware_interface/EffortJointInterface</hardwareInterface>
    </joint>
    <actuator name="Revolute 2_actr">
      <hardwareInterface>hardware_interface/EffortJointInterface</hardwareInterface>
      <mechanicalReduction>1</mechanicalReduction>
    </actuator>
  </transmission>
  <transmission name="Revolute 3_tran">
    <type>transmission_interface/SimpleTransmission</type>
    <joint name="Revolute 3">
      <hardwareInterface>hardware_interface/EffortJointInterface</hardwareInterface>
    </joint>
    <actuator name="Revolute 3_actr">
      <hardwareInterface>hardware_interface/EffortJointInterface</hardwareInterface>
      <mechanicalReduction>1</mechanicalReduction>
    </actuator>
  </transmission>
  <transmission name="Revolute 4_tran">
    <type>transmission_interface/SimpleTransmission</type>
    <joint name="Revolute 4">
      <hardwareInterface>hardware_interface/EffortJointInterface</hardwareInterface>
    </joint>
    <actuator name="Revolute 4_actr">
      <hardwareInterface>hardware_interface/EffortJointInterface</hardwareInterface>
      <mechanicalReduction>1</mechanicalReduction>
    </actuator>
  </transmission>
  <transmission name="Revolute 6_tran">
    <type>transmission_interface/SimpleTransmission</type>
    <joint name="Revolute 6">
      <hardwareInterface>hardware_interface/EffortJointInterface</hardwareInterface>
    </joint>
    <actuator name="Revolute 6_actr">
      <hardwareInterface>hardware_interface/EffortJointInterface</hardwareInterface>
      <mechanicalReduction>1</mechanicalReduction>
    </actuator>
  </transmission>
  <transmission name="Revolute 7_tran">
    <type>transmission_interface/SimpleTransmission</type>
    <joint name="Revolute 7">
      <hardwareInterface>hardware_interface/EffortJointInterface</hardwareInterface>
    </joint>
    <actuator name="Revolute 7_actr">
      <hardwareInterface>hardware_interface/EffortJointInterface</hardwareInterface>
      <mechanicalReduction>1</mechanicalReduction>
    </actuator>
  </transmission>
  <transmission name="Revolute 8_tran">
    <type>transmission_interface/SimpleTransmission</type>
    <joint name="Revolute 8">
      <hardwareInterface>hardware_interface/EffortJointInterface</hardwareInterface>
    </joint>
    <actuator name="Revolute 8_actr">
      <hardwareInterface>hardware_interface/EffortJointInterface</hardwareInterface>
      <mechanicalReduction>1</mechanicalReduction>
    </actuator>
  </transmission>
  <transmission name="Revolute 9_tran">
    <type>transmission_interface/SimpleTransmission</type>
    <joint name="Revolute 9">
      <hardwareInterface>hardware_interface/EffortJointInterface</hardwareInterface>
    </joint>
    <actuator name="Revolute 9_actr">
      <hardwareInterface>hardware_interface/EffortJointInterface</hardwareInterface>
      <mechanicalReduction>1</mechanicalReduction>
    </actuator>
  </transmission>
  <!-- omitted .gazebo include -->
  <link name="base_link">
    <inertial>
      <origin xyz="2.989375374043843 1.1395251464843752 0.07612872006595212" rpy="0 0 0"/>
      <mass value="1.6067306789990348"/>
      <inertia ixx="0.003521" iyy="0.006468" izz="0.008802" ixy="0.0" iyz="0.0" ixz="0.0"/>
    </inertial>
    <visual>
      <origin xyz="0 0 0" rpy="0 0 0"/>
      <geometry>
        <mesh filename="robot_ver7_description/meshes/base_link.stl" scale="0.001 0.001 0.001"/>
      </geometry>
      <material name="silver"/>
    </visual>
    <collision>
      <origin xyz="0 0 0" rpy="0 0 0"/>
      <geometry>
        <mesh filename="robot_ver7_description/meshes/base_link.stl" scale="0.001 0.001 0.001"/>
      </geometry>
    </collision>
  </link>
  <link name="link_1_1">
    <inertial>
      <origin xyz="2.079701455492966e-07 1.4648437618447474e-07 0.04484473463010137" rpy="0 0 0"/>
      <mass value="0.8724221516717876"/>
      <inertia ixx="0.000529" iyy="0.000636" izz="0.000308" ixy="-0.0" iyz="-0.0" ixz="-0.0"/>
    </inertial>
    <visual>
      <origin xyz="-2.989375 -1.139525 -0.122186" rpy="0 0 0"/>
      <geometry>
        <mesh filename="robot_ver7_description/meshes/link_1_1.stl" scale="0.001 0.001 0.001"/>
      </geometry>
      <material name="silver"/>
    </visual>
    <collision>
      <origin xyz="-2.989375 -1.139525 -0.122186" rpy="0 0 0"/>
      <geometry>
        <mesh filename="robot_ver7_description/meshes/link_1_1.stl" scale="0.001 0.001 0.001"/>
      </geometry>
    </collision>
  </link>
  <link name="link_2_1">
    <inertial>
      <origin xyz="2.938858791878829e-07 1.4648438195763447e-07 0.13199352594951688" rpy="0 0 0"/>
      <mass value="1.7894494256516804"/>
      <inertia ixx="0.007559" iyy="0.007762" izz="0.000473" ixy="0.0" iyz="0.0" ixz="0.0"/>
    </inertial>
    <visual>
      <origin xyz="-2.989375 -1.139525 -0.192528" rpy="0 0 0"/>
      <geometry>
        <mesh filename="robot_ver7_description/meshes/link_2_1.stl" scale="0.001 0.001 0.001"/>
      </geometry>
      <material name="silver"/>
    </visual>
    <collision>
      <origin xyz="-2.989375 -1.139525 -0.192528" rpy="0 0 0"/>
      <geometry>
        <mesh filename="robot_ver7_description/meshes/link_2_1.stl" scale="0.001 0.001 0.001"/>
      </geometry>
    </collision>
  </link>
  <link name="link_3_1">
    <inertial>
      <origin xyz="3.756619166850328e-07 0.008180253565493123 0.1490707247075182" rpy="0 0 0"/>
      <mass value="2.3011672222568587"/>
      <inertia ixx="0.010731" iyy="0.010238" izz="0.001122" ixy="-0.0" iyz="-0.001076" ixz="0.0"/>
    </inertial>
    <visual>
      <origin xyz="-2.989375 -1.139525 -0.40687" rpy="0 0 0"/>
      <geometry>
        <mesh filename="robot_ver7_description/meshes/link_3_1.stl" scale="0.001 0.001 0.001"/>
      </geometry>
      <material name="silver"/>
    </visual>
    <collision>
      <origin xyz="-2.989375 -1.139525 -0.40687" rpy="0 0 0"/>
      <geometry>
        <mesh filename="robot_ver7_description/meshes/link_3_1.stl" scale="0.001 0.001 0.001"/>
      </geometry>
    </collision>
  </link>
  <link name="link_4_1">
    <inertial>
      <origin xyz="3.7566188737514494e-07 1.4648436263975384e-07 0.018168573469312888" rpy="0 0 0"/>
      <mass value="0.1836674229836166"/>
      <inertia ixx="7.1e-05" iyy="0.000103" izz="0.0001" ixy="0.0" iyz="0.0" ixz="0.0"/>
    </inertial>
    <visual>
      <origin xyz="-2.989375 -1.138027 -0.64097" rpy="0 0 0"/>
      <geometry>
        <mesh filename="robot_ver7_description/meshes/link_4_1.stl" scale="0.001 0.001 0.001"/>
      </geometry>
      <material name="silver"/>
    </visual>
    <collision>
      <origin xyz="-2.989375 -1.138027 -0.64097" rpy="0 0 0"/>
      <geometry>
        <mesh filename="robot_ver7_description/meshes/link_4_1.stl" scale="0.001 0.001 0.001"/>
      </geometry>
    </collision>
  </link>
  <link name="grap_1_1">
    <inertial>
      <origin xyz="0.0011129810331476087 0.032768250662570164 0.005980783412323998" rpy="0 0 0"/>
      <mass value="0.04062678364093055"/>
      <inertia ixx="2.7e-05" iyy="6e-06" izz="2.3e-05" ixy="-2e-06" iyz="-7e-06" ixz="-1e-06"/>
    </inertial>
    <visual>
      <origin xyz="-2.964375 -1.150527 -0.68317" rpy="0 0 0"/>
      <geometry>
        <mesh filename="robot_ver7_description/meshes/grap_1_1.stl" scale="0.001 0.001 0.001"/>
      </geometry>
      <material name="silver"/>
    </visual>
    <collision>
      <origin xyz="-2.964375 -1.150527 -0.68317" rpy="0 0 0"/>
      <geometry>
        <mesh filename="robot_ver7_description/meshes/grap_1_1.stl" scale="0.001 0.001 0.001"/>
      </geometry>
    </collision>
  </link>
  <link name="grap_2_1">
    <inertial>
      <origin xyz="0.001112981033148941 -0.032767957693844885 0.0059807834123277726" rpy="0 0 0"/>
      <mass value="0.040626783640931016"/>
      <inertia ixx="2.7e-05" iyy="6e-06" izz="2.3e-05" ixy="2e-06" iyz="7e-06" ixz="-1e-06"/>
    </inertial>
    <visual>
      <origin xyz="-2.964375 -1.125527 -0.68317" rpy="0 0 0"/>
      <geometry>
        <mesh filename="robot_ver7_description/meshes/grap_2_1.stl" scale="0.001 0.001 0.001"/>
      </geometry>
      <material name="silver"/>
    </visual>
    <collision>
      <origin xyz="-2.964375 -1.125527 -0.68317" rpy="0 0 0"/>
      <geometry>
        <mesh filename="robot_ver7_description/meshes/grap_2_1.stl" scale="0.001 0.001 0.001"/>
      </geometry>
    </collision>
  </link>
  <link name="grap1_2_1">
    <inertial>
      <origin xyz="-0.0011122297093195677 0.032768250662569276 0.005980783412327106" rpy="0 0 0"/>
      <mass value="0.040626783640930565"/>
      <inertia ixx="2.7e-05" iyy="6e-06" izz="2.3e-05" ixy="2e-06" iyz="-7e-06" ixz="1e-06"/>
    </inertial>
    <visual>
      <origin xyz="-3.014375 -1.150527 -0.68317" rpy="0 0 0"/>
      <geometry>
        <mesh filename="robot_ver7_description/meshes/grap1_2_1.stl" scale="0.001 0.001 0.001"/>
      </geometry>
      <material name="silver"/>
    </visual>
    <collision>
      <origin xyz="-3.014375 -1.150527 -0.68317" rpy="0 0 0"/>
      <geometry>
        <mesh filename="robot_ver7_description/meshes/grap1_2_1.stl" scale="0.001 0.001 0.001"/>
      </geometry>
    </collision>
  </link>
  <link name="grap2_2_1">
    <inertial>
      <origin xyz="-0.0011122297093182354 -0.03276795769384622 0.005980783412324442" rpy="0 0 0"/>
      <mass value="0.040626783640930315"/>
      <inertia ixx="2.7e-05" iyy="6e-06" izz="2.3e-05" ixy="-2e-06" iyz="7e-06" ixz="1e-06"/>
    </inertial>
    <visual>
      <origin xyz="-3.014375 -1.125527 -0.68317" rpy="0 0 0"/>
      <geometry>
        <mesh filename="robot_ver7_description/meshes/grap2_2_1.stl" scale="0.001 0.001 0.001"/>
      </geometry>
      <material name="silver"/>
    </visual>
    <collision>
      <origin xyz="-3.014375 -1.125527 -0.68317" rpy="0 0 0"/>
      <geometry>
        <mesh filename="robot_ver7_description/meshes/grap2_2_1.stl" scale="0.001 0.001 0.001"/>
      </geometry>
    </collision>
  </link>
  <joint name="Revolute 1" type="revolute">
    <origin xyz="2.989375 1.139525 0.122186" rpy="0 0 0"/>
    <parent link="base_link"/>
    <child link="link_1_1"/>
    <axis xyz="0.0 0.0 1.0"/>
    <limit lower="-1.5708" upper="1.5708" />  
  </joint>
  <joint name="Revolute 2" type="revolute">
    <origin xyz="0.0 0.0 0.070342" rpy="0 0 0"/>
    <parent link="link_1_1"/>
    <child link="link_2_1"/>
    <axis xyz="-1.0 0.0 -0.0"/>
    <limit lower="-1.5708" upper="1.39626" />
  </joint>
  <joint name="Revolute 3" type="revolute">
    <origin xyz="0.0 0.0 0.214342" rpy="0 0 0"/>
    <parent link="link_2_1"/>
    <child link="link_3_1"/>
    <axis xyz="-1.0 0.0 -0.0"/>
    <limit lower="0.349066" upper="1.91986" />  
  </joint>
  <joint name="Revolute 4" type="revolute">
    <origin xyz="0.0 -0.001498 0.2341" rpy="0 0 0"/>
    <parent link="link_3_1"/>
    <child link="link_4_1"/>
    <axis xyz="-0.0 0.0 1.0"/>
    <limit lower="0" upper="3.14159" />  
  </joint>
  <joint name="Revolute 6" type="revolute">
    <origin xyz="-0.025 0.0125 0.0422" rpy="0 0 0"/>
    <parent link="link_4_1"/>
    <child link="grap_1_1"/>
    <axis xyz="-1.0 -0.0 -0.0"/>
    <limit lower="0" upper="3.14" /> 
  </joint>
  <joint name="Revolute 7" type="revolute">
    <origin xyz="-0.025 -0.0125 0.0422" rpy="0 0 0"/>
    <parent link="link_4_1"/>
    <child link="grap_2_1"/>
    <axis xyz="-1.0 -0.0 -0.0"/>
    <limit lower="0" upper="3.14" /> 
  </joint>
  <joint name="Revolute 8" type="revolute">
    <origin xyz="0.025 0.0125 0.0422" rpy="0 0 0"/>
    <parent link="link_4_1"/>
    <child link="grap1_2_1"/>
    <axis xyz="1.0 -0.0 0.0"/>
    <limit lower="0" upper="3.14" /> 
  </joint>
  <joint name="Revolute 9" type="revolute">
    <origin xyz="0.025 -0.0125 0.0422" rpy="0 0 0"/>
    <parent link="link_4_1"/>
    <child link="grap2_2_1"/>
    <axis xyz="1.0 0.0 0.0"/>
    <limit lower="0" upper="3.14" /> 
  </joint>
</robot>
